{
 "cells": [
  {
   "cell_type": "code",
   "execution_count": 1,
   "id": "23e8a857",
   "metadata": {},
   "outputs": [
    {
     "name": "stderr",
     "output_type": "stream",
     "text": [
      "/home/polivares/anaconda3/envs/DataScience/lib/python3.8/site-packages/tqdm/auto.py:22: TqdmWarning: IProgress not found. Please update jupyter and ipywidgets. See https://ipywidgets.readthedocs.io/en/stable/user_install.html\n",
      "  from .autonotebook import tqdm as notebook_tqdm\n"
     ]
    }
   ],
   "source": [
    "import tensorflow_datasets as tfds"
   ]
  },
  {
   "cell_type": "code",
   "execution_count": null,
   "id": "561b343f",
   "metadata": {},
   "outputs": [],
   "source": [
    "dataset, info = tfds.load(\"tf_flowers\", as_supervised=True, with_info=True)"
   ]
  },
  {
   "cell_type": "code",
   "execution_count": 3,
   "id": "51a80797",
   "metadata": {},
   "outputs": [],
   "source": [
    "test_set, valid_set, train_set = tfds.load(\"tf_flowers\",split=[\"train[0%:10%]\", \"train[10%:25%]\", \"train[25%:]\"], as_supervised=True )"
   ]
  },
  {
   "cell_type": "code",
   "execution_count": 4,
   "id": "da563b5f",
   "metadata": {},
   "outputs": [],
   "source": [
    "import tensorflow as tf"
   ]
  },
  {
   "cell_type": "code",
   "execution_count": 6,
   "id": "b69ee555",
   "metadata": {},
   "outputs": [],
   "source": [
    "# Previo a la utilización de nuestro dataset en la red neuronal, la red que utilizaremos provee de\n",
    "# funcionalidades de pre-procesamiento ya incluídas. Por lo tanto, utilizaremos estas funcionalidades\n",
    "# y las dejaremos dentro de una función\n",
    "def preprocess(image, label):\n",
    "    # Cambiaremos las dimensiones de la imagen de entrada\n",
    "    resized_image = tf.image.resize(image, [224, 224]) # Guardamos la imagen con nuevas dimensiones 224x224\n",
    "    # Luego pasamos la imagen modificada en tamaño al preprocesamiento de nuestra red. La red\n",
    "    # que utilizaremos de ejemplo tiene por nombre Xception\n",
    "    final_image = tf.keras.applications.xception.preprocess_input(resized_image)\n",
    "    # Finalmente se retorna una imagen pre procesada (según lo indique el preprocess de xception)\n",
    "    # y su etiqueta\n",
    "    return final_image, label"
   ]
  },
  {
   "cell_type": "code",
   "execution_count": 7,
   "id": "bd9708fe",
   "metadata": {},
   "outputs": [],
   "source": [
    "# En este apartado hacemos los batch de datos directamente desde el dataset cargado por tensorflow\n",
    "batch_size = 32\n",
    "\n",
    "# Mezclamos el dataset \n",
    "train_set = train_set.shuffle(1000)\n",
    "# Tanto para training, test y validación, aplicamos la función de preprocesamiento (preprocess)\n",
    "# y luego generamos los batch de datos\n",
    "train_set = train_set.map(preprocess).batch(batch_size).prefetch(1)\n",
    "test_set = test_set.map(preprocess).batch(batch_size).prefetch(1)\n",
    "valid_set = valid_set.map(preprocess).batch(batch_size).prefetch(1)"
   ]
  },
  {
   "cell_type": "code",
   "execution_count": 8,
   "id": "04dfb8d6",
   "metadata": {},
   "outputs": [],
   "source": [
    "# Acá empezamos con transfer learning. Lo que haremos será cargar una arquitectura de red neuronal desde\n",
    "# tensorflow ya entrenada. Eso quiere decir que, no solo estamos cargando la arquitectura, con sus neuronas\n",
    "# y conexiones, sino que también estamos cargando los PESOS DE ENTRENAMIENTO.\n",
    "\n",
    "# Weights indica si utilizaremos pesos pre entrenados con el dataset imagenet o no\n",
    "# include_top es el parámetro que indica explícitamente si quieres o no la capa de salida original\n",
    "# de esta red.\n",
    "# En base_model tenemos cargado nuestro modelo Xception sin la capa de salida. Nosotros podemos\n",
    "# poner NUESTRA PROPIA CAPA(S) DE SALIDA\n",
    "base_model = tf.keras.applications.xception.Xception(weights=\"imagenet\", include_top=False)\n",
    "# Acá agregamos nuestras capas adicionales\n",
    "avg = tf.keras.layers.GlobalAveragePooling2D()(base_model.output)\n",
    "output = tf.keras.layers.Dense(5, activation=\"softmax\")(avg)\n",
    "\n",
    "# Podemos conectar el input de nuestro modelo base con el output recién generado a través de \n",
    "# un modelo de Keras\n",
    "model = tf.keras.Model(inputs=base_model.input, outputs=output)\n",
    "# En este punto tenemos un nuevo modelo que utiliza como base la arquitectura Xception"
   ]
  },
  {
   "cell_type": "code",
   "execution_count": null,
   "id": "76001e53",
   "metadata": {},
   "outputs": [],
   "source": [
    "# También nosotros conversamos que es posible decidir si queremos reentrenar aquellas capas ya entrenadas\n",
    "\n",
    "# Acá vamos capa por capa modificando el parámetro \"trainable\" que permite (o no) reentrenar dicha capa\n",
    "for layer in base_model.layers:\n",
    "    layer.trainable = False # Esto impide que las capas se re entrenen\n",
    "\n",
    "# Con este for, sobre todas las capas de nuestro modelo, estamos impidiendo que se reentrene\n",
    "# alguna de sus capas ya entrenadas"
   ]
  },
  {
   "cell_type": "code",
   "execution_count": 9,
   "id": "af9e8d0c",
   "metadata": {},
   "outputs": [],
   "source": [
    "# Proceso de compilación  (tal cual vimos en las clases anteriores)\n",
    "model.compile(loss=\"sparse_categorical_crossentropy\", optimizer=\"sgd\", \n",
    "              metrics=[\"accuracy\"])"
   ]
  },
  {
   "cell_type": "code",
   "execution_count": 11,
   "id": "0f394ae1",
   "metadata": {},
   "outputs": [
    {
     "name": "stdout",
     "output_type": "stream",
     "text": [
      "Epoch 1/10\n"
     ]
    },
    {
     "name": "stderr",
     "output_type": "stream",
     "text": [
      "2023-05-23 20:44:58.759675: W tensorflow/core/framework/op_kernel.cc:1745] OP_REQUIRES failed at conv_ops.cc:1120 : NOT_FOUND: No algorithm worked!  Error messages:\n",
      "  Profiling failure on CUDNN engine 1#TC: RESOURCE_EXHAUSTED: Out of memory while trying to allocate 51838992 bytes.\n",
      "  Profiling failure on CUDNN engine 1: RESOURCE_EXHAUSTED: Out of memory while trying to allocate 29368704 bytes.\n",
      "  Profiling failure on CUDNN engine 0#TC: RESOURCE_EXHAUSTED: Out of memory while trying to allocate 16777216 bytes.\n",
      "  Profiling failure on CUDNN engine 0: RESOURCE_EXHAUSTED: Out of memory while trying to allocate 16777216 bytes.\n",
      "  Profiling failure on CUDNN engine 2#TC: RESOURCE_EXHAUSTED: Out of memory while trying to allocate 26411008 bytes.\n",
      "  Profiling failure on CUDNN engine 2: RESOURCE_EXHAUSTED: Out of memory while trying to allocate 26411008 bytes.\n",
      "  Profiling failure on CUDNN engine 5#TC: RESOURCE_EXHAUSTED: Out of memory while trying to allocate 553779200 bytes.\n",
      "  Profiling failure on CUDNN engine 5: RESOURCE_EXHAUSTED: Out of memory while trying to allocate 553779200 bytes.\n"
     ]
    },
    {
     "ename": "NotFoundError",
     "evalue": "Graph execution error:\n\nDetected at node 'model/block14_sepconv2/separable_conv2d' defined at (most recent call last):\n    File \"/home/polivares/anaconda3/envs/DataScience/lib/python3.8/runpy.py\", line 194, in _run_module_as_main\n      return _run_code(code, main_globals, None,\n    File \"/home/polivares/anaconda3/envs/DataScience/lib/python3.8/runpy.py\", line 87, in _run_code\n      exec(code, run_globals)\n    File \"/home/polivares/anaconda3/envs/DataScience/lib/python3.8/site-packages/ipykernel_launcher.py\", line 17, in <module>\n      app.launch_new_instance()\n    File \"/home/polivares/anaconda3/envs/DataScience/lib/python3.8/site-packages/traitlets/config/application.py\", line 982, in launch_instance\n      app.start()\n    File \"/home/polivares/anaconda3/envs/DataScience/lib/python3.8/site-packages/ipykernel/kernelapp.py\", line 712, in start\n      self.io_loop.start()\n    File \"/home/polivares/anaconda3/envs/DataScience/lib/python3.8/site-packages/tornado/platform/asyncio.py\", line 215, in start\n      self.asyncio_loop.run_forever()\n    File \"/home/polivares/anaconda3/envs/DataScience/lib/python3.8/asyncio/base_events.py\", line 570, in run_forever\n      self._run_once()\n    File \"/home/polivares/anaconda3/envs/DataScience/lib/python3.8/asyncio/base_events.py\", line 1859, in _run_once\n      handle._run()\n    File \"/home/polivares/anaconda3/envs/DataScience/lib/python3.8/asyncio/events.py\", line 81, in _run\n      self._context.run(self._callback, *self._args)\n    File \"/home/polivares/anaconda3/envs/DataScience/lib/python3.8/site-packages/ipykernel/kernelbase.py\", line 510, in dispatch_queue\n      await self.process_one()\n    File \"/home/polivares/anaconda3/envs/DataScience/lib/python3.8/site-packages/ipykernel/kernelbase.py\", line 499, in process_one\n      await dispatch(*args)\n    File \"/home/polivares/anaconda3/envs/DataScience/lib/python3.8/site-packages/ipykernel/kernelbase.py\", line 406, in dispatch_shell\n      await result\n    File \"/home/polivares/anaconda3/envs/DataScience/lib/python3.8/site-packages/ipykernel/kernelbase.py\", line 730, in execute_request\n      reply_content = await reply_content\n    File \"/home/polivares/anaconda3/envs/DataScience/lib/python3.8/site-packages/ipykernel/ipkernel.py\", line 383, in do_execute\n      res = shell.run_cell(\n    File \"/home/polivares/anaconda3/envs/DataScience/lib/python3.8/site-packages/ipykernel/zmqshell.py\", line 528, in run_cell\n      return super().run_cell(*args, **kwargs)\n    File \"/home/polivares/anaconda3/envs/DataScience/lib/python3.8/site-packages/IPython/core/interactiveshell.py\", line 2940, in run_cell\n      result = self._run_cell(\n    File \"/home/polivares/anaconda3/envs/DataScience/lib/python3.8/site-packages/IPython/core/interactiveshell.py\", line 2995, in _run_cell\n      return runner(coro)\n    File \"/home/polivares/anaconda3/envs/DataScience/lib/python3.8/site-packages/IPython/core/async_helpers.py\", line 129, in _pseudo_sync_runner\n      coro.send(None)\n    File \"/home/polivares/anaconda3/envs/DataScience/lib/python3.8/site-packages/IPython/core/interactiveshell.py\", line 3194, in run_cell_async\n      has_raised = await self.run_ast_nodes(code_ast.body, cell_name,\n    File \"/home/polivares/anaconda3/envs/DataScience/lib/python3.8/site-packages/IPython/core/interactiveshell.py\", line 3373, in run_ast_nodes\n      if await self.run_code(code, result, async_=asy):\n    File \"/home/polivares/anaconda3/envs/DataScience/lib/python3.8/site-packages/IPython/core/interactiveshell.py\", line 3433, in run_code\n      exec(code_obj, self.user_global_ns, self.user_ns)\n    File \"/tmp/ipykernel_9160/3551155534.py\", line 1, in <module>\n      history = model.fit(train_set, epochs=10, validation_data=valid_set)\n    File \"/home/polivares/anaconda3/envs/DataScience/lib/python3.8/site-packages/keras/utils/traceback_utils.py\", line 64, in error_handler\n      return fn(*args, **kwargs)\n    File \"/home/polivares/anaconda3/envs/DataScience/lib/python3.8/site-packages/keras/engine/training.py\", line 1384, in fit\n      tmp_logs = self.train_function(iterator)\n    File \"/home/polivares/anaconda3/envs/DataScience/lib/python3.8/site-packages/keras/engine/training.py\", line 1021, in train_function\n      return step_function(self, iterator)\n    File \"/home/polivares/anaconda3/envs/DataScience/lib/python3.8/site-packages/keras/engine/training.py\", line 1010, in step_function\n      outputs = model.distribute_strategy.run(run_step, args=(data,))\n    File \"/home/polivares/anaconda3/envs/DataScience/lib/python3.8/site-packages/keras/engine/training.py\", line 1000, in run_step\n      outputs = model.train_step(data)\n    File \"/home/polivares/anaconda3/envs/DataScience/lib/python3.8/site-packages/keras/engine/training.py\", line 859, in train_step\n      y_pred = self(x, training=True)\n    File \"/home/polivares/anaconda3/envs/DataScience/lib/python3.8/site-packages/keras/utils/traceback_utils.py\", line 64, in error_handler\n      return fn(*args, **kwargs)\n    File \"/home/polivares/anaconda3/envs/DataScience/lib/python3.8/site-packages/keras/engine/base_layer.py\", line 1096, in __call__\n      outputs = call_fn(inputs, *args, **kwargs)\n    File \"/home/polivares/anaconda3/envs/DataScience/lib/python3.8/site-packages/keras/utils/traceback_utils.py\", line 92, in error_handler\n      return fn(*args, **kwargs)\n    File \"/home/polivares/anaconda3/envs/DataScience/lib/python3.8/site-packages/keras/engine/functional.py\", line 451, in call\n      return self._run_internal_graph(\n    File \"/home/polivares/anaconda3/envs/DataScience/lib/python3.8/site-packages/keras/engine/functional.py\", line 589, in _run_internal_graph\n      outputs = node.layer(*args, **kwargs)\n    File \"/home/polivares/anaconda3/envs/DataScience/lib/python3.8/site-packages/keras/utils/traceback_utils.py\", line 64, in error_handler\n      return fn(*args, **kwargs)\n    File \"/home/polivares/anaconda3/envs/DataScience/lib/python3.8/site-packages/keras/engine/base_layer.py\", line 1096, in __call__\n      outputs = call_fn(inputs, *args, **kwargs)\n    File \"/home/polivares/anaconda3/envs/DataScience/lib/python3.8/site-packages/keras/utils/traceback_utils.py\", line 92, in error_handler\n      return fn(*args, **kwargs)\n    File \"/home/polivares/anaconda3/envs/DataScience/lib/python3.8/site-packages/keras/layers/convolutional.py\", line 2255, in call\n      outputs = tf.compat.v1.nn.separable_conv2d(\nNode: 'model/block14_sepconv2/separable_conv2d'\nNo algorithm worked!  Error messages:\n  Profiling failure on CUDNN engine 1#TC: RESOURCE_EXHAUSTED: Out of memory while trying to allocate 51838992 bytes.\n  Profiling failure on CUDNN engine 1: RESOURCE_EXHAUSTED: Out of memory while trying to allocate 29368704 bytes.\n  Profiling failure on CUDNN engine 0#TC: RESOURCE_EXHAUSTED: Out of memory while trying to allocate 16777216 bytes.\n  Profiling failure on CUDNN engine 0: RESOURCE_EXHAUSTED: Out of memory while trying to allocate 16777216 bytes.\n  Profiling failure on CUDNN engine 2#TC: RESOURCE_EXHAUSTED: Out of memory while trying to allocate 26411008 bytes.\n  Profiling failure on CUDNN engine 2: RESOURCE_EXHAUSTED: Out of memory while trying to allocate 26411008 bytes.\n  Profiling failure on CUDNN engine 5#TC: RESOURCE_EXHAUSTED: Out of memory while trying to allocate 553779200 bytes.\n  Profiling failure on CUDNN engine 5: RESOURCE_EXHAUSTED: Out of memory while trying to allocate 553779200 bytes.\n\t [[{{node model/block14_sepconv2/separable_conv2d}}]] [Op:__inference_train_function_8560]",
     "output_type": "error",
     "traceback": [
      "\u001b[0;31m---------------------------------------------------------------------------\u001b[0m",
      "\u001b[0;31mNotFoundError\u001b[0m                             Traceback (most recent call last)",
      "Cell \u001b[0;32mIn [11], line 1\u001b[0m\n\u001b[0;32m----> 1\u001b[0m history \u001b[38;5;241m=\u001b[39m \u001b[43mmodel\u001b[49m\u001b[38;5;241;43m.\u001b[39;49m\u001b[43mfit\u001b[49m\u001b[43m(\u001b[49m\u001b[43mtrain_set\u001b[49m\u001b[43m,\u001b[49m\u001b[43m \u001b[49m\u001b[43mepochs\u001b[49m\u001b[38;5;241;43m=\u001b[39;49m\u001b[38;5;241;43m10\u001b[39;49m\u001b[43m,\u001b[49m\u001b[43m \u001b[49m\u001b[43mvalidation_data\u001b[49m\u001b[38;5;241;43m=\u001b[39;49m\u001b[43mvalid_set\u001b[49m\u001b[43m)\u001b[49m\n",
      "File \u001b[0;32m~/anaconda3/envs/DataScience/lib/python3.8/site-packages/keras/utils/traceback_utils.py:67\u001b[0m, in \u001b[0;36mfilter_traceback.<locals>.error_handler\u001b[0;34m(*args, **kwargs)\u001b[0m\n\u001b[1;32m     65\u001b[0m \u001b[38;5;28;01mexcept\u001b[39;00m \u001b[38;5;167;01mException\u001b[39;00m \u001b[38;5;28;01mas\u001b[39;00m e:  \u001b[38;5;66;03m# pylint: disable=broad-except\u001b[39;00m\n\u001b[1;32m     66\u001b[0m   filtered_tb \u001b[38;5;241m=\u001b[39m _process_traceback_frames(e\u001b[38;5;241m.\u001b[39m__traceback__)\n\u001b[0;32m---> 67\u001b[0m   \u001b[38;5;28;01mraise\u001b[39;00m e\u001b[38;5;241m.\u001b[39mwith_traceback(filtered_tb) \u001b[38;5;28;01mfrom\u001b[39;00m \u001b[38;5;28mNone\u001b[39m\n\u001b[1;32m     68\u001b[0m \u001b[38;5;28;01mfinally\u001b[39;00m:\n\u001b[1;32m     69\u001b[0m   \u001b[38;5;28;01mdel\u001b[39;00m filtered_tb\n",
      "File \u001b[0;32m~/anaconda3/envs/DataScience/lib/python3.8/site-packages/tensorflow/python/eager/execute.py:54\u001b[0m, in \u001b[0;36mquick_execute\u001b[0;34m(op_name, num_outputs, inputs, attrs, ctx, name)\u001b[0m\n\u001b[1;32m     52\u001b[0m \u001b[38;5;28;01mtry\u001b[39;00m:\n\u001b[1;32m     53\u001b[0m   ctx\u001b[38;5;241m.\u001b[39mensure_initialized()\n\u001b[0;32m---> 54\u001b[0m   tensors \u001b[38;5;241m=\u001b[39m pywrap_tfe\u001b[38;5;241m.\u001b[39mTFE_Py_Execute(ctx\u001b[38;5;241m.\u001b[39m_handle, device_name, op_name,\n\u001b[1;32m     55\u001b[0m                                       inputs, attrs, num_outputs)\n\u001b[1;32m     56\u001b[0m \u001b[38;5;28;01mexcept\u001b[39;00m core\u001b[38;5;241m.\u001b[39m_NotOkStatusException \u001b[38;5;28;01mas\u001b[39;00m e:\n\u001b[1;32m     57\u001b[0m   \u001b[38;5;28;01mif\u001b[39;00m name \u001b[38;5;129;01mis\u001b[39;00m \u001b[38;5;129;01mnot\u001b[39;00m \u001b[38;5;28;01mNone\u001b[39;00m:\n",
      "\u001b[0;31mNotFoundError\u001b[0m: Graph execution error:\n\nDetected at node 'model/block14_sepconv2/separable_conv2d' defined at (most recent call last):\n    File \"/home/polivares/anaconda3/envs/DataScience/lib/python3.8/runpy.py\", line 194, in _run_module_as_main\n      return _run_code(code, main_globals, None,\n    File \"/home/polivares/anaconda3/envs/DataScience/lib/python3.8/runpy.py\", line 87, in _run_code\n      exec(code, run_globals)\n    File \"/home/polivares/anaconda3/envs/DataScience/lib/python3.8/site-packages/ipykernel_launcher.py\", line 17, in <module>\n      app.launch_new_instance()\n    File \"/home/polivares/anaconda3/envs/DataScience/lib/python3.8/site-packages/traitlets/config/application.py\", line 982, in launch_instance\n      app.start()\n    File \"/home/polivares/anaconda3/envs/DataScience/lib/python3.8/site-packages/ipykernel/kernelapp.py\", line 712, in start\n      self.io_loop.start()\n    File \"/home/polivares/anaconda3/envs/DataScience/lib/python3.8/site-packages/tornado/platform/asyncio.py\", line 215, in start\n      self.asyncio_loop.run_forever()\n    File \"/home/polivares/anaconda3/envs/DataScience/lib/python3.8/asyncio/base_events.py\", line 570, in run_forever\n      self._run_once()\n    File \"/home/polivares/anaconda3/envs/DataScience/lib/python3.8/asyncio/base_events.py\", line 1859, in _run_once\n      handle._run()\n    File \"/home/polivares/anaconda3/envs/DataScience/lib/python3.8/asyncio/events.py\", line 81, in _run\n      self._context.run(self._callback, *self._args)\n    File \"/home/polivares/anaconda3/envs/DataScience/lib/python3.8/site-packages/ipykernel/kernelbase.py\", line 510, in dispatch_queue\n      await self.process_one()\n    File \"/home/polivares/anaconda3/envs/DataScience/lib/python3.8/site-packages/ipykernel/kernelbase.py\", line 499, in process_one\n      await dispatch(*args)\n    File \"/home/polivares/anaconda3/envs/DataScience/lib/python3.8/site-packages/ipykernel/kernelbase.py\", line 406, in dispatch_shell\n      await result\n    File \"/home/polivares/anaconda3/envs/DataScience/lib/python3.8/site-packages/ipykernel/kernelbase.py\", line 730, in execute_request\n      reply_content = await reply_content\n    File \"/home/polivares/anaconda3/envs/DataScience/lib/python3.8/site-packages/ipykernel/ipkernel.py\", line 383, in do_execute\n      res = shell.run_cell(\n    File \"/home/polivares/anaconda3/envs/DataScience/lib/python3.8/site-packages/ipykernel/zmqshell.py\", line 528, in run_cell\n      return super().run_cell(*args, **kwargs)\n    File \"/home/polivares/anaconda3/envs/DataScience/lib/python3.8/site-packages/IPython/core/interactiveshell.py\", line 2940, in run_cell\n      result = self._run_cell(\n    File \"/home/polivares/anaconda3/envs/DataScience/lib/python3.8/site-packages/IPython/core/interactiveshell.py\", line 2995, in _run_cell\n      return runner(coro)\n    File \"/home/polivares/anaconda3/envs/DataScience/lib/python3.8/site-packages/IPython/core/async_helpers.py\", line 129, in _pseudo_sync_runner\n      coro.send(None)\n    File \"/home/polivares/anaconda3/envs/DataScience/lib/python3.8/site-packages/IPython/core/interactiveshell.py\", line 3194, in run_cell_async\n      has_raised = await self.run_ast_nodes(code_ast.body, cell_name,\n    File \"/home/polivares/anaconda3/envs/DataScience/lib/python3.8/site-packages/IPython/core/interactiveshell.py\", line 3373, in run_ast_nodes\n      if await self.run_code(code, result, async_=asy):\n    File \"/home/polivares/anaconda3/envs/DataScience/lib/python3.8/site-packages/IPython/core/interactiveshell.py\", line 3433, in run_code\n      exec(code_obj, self.user_global_ns, self.user_ns)\n    File \"/tmp/ipykernel_9160/3551155534.py\", line 1, in <module>\n      history = model.fit(train_set, epochs=10, validation_data=valid_set)\n    File \"/home/polivares/anaconda3/envs/DataScience/lib/python3.8/site-packages/keras/utils/traceback_utils.py\", line 64, in error_handler\n      return fn(*args, **kwargs)\n    File \"/home/polivares/anaconda3/envs/DataScience/lib/python3.8/site-packages/keras/engine/training.py\", line 1384, in fit\n      tmp_logs = self.train_function(iterator)\n    File \"/home/polivares/anaconda3/envs/DataScience/lib/python3.8/site-packages/keras/engine/training.py\", line 1021, in train_function\n      return step_function(self, iterator)\n    File \"/home/polivares/anaconda3/envs/DataScience/lib/python3.8/site-packages/keras/engine/training.py\", line 1010, in step_function\n      outputs = model.distribute_strategy.run(run_step, args=(data,))\n    File \"/home/polivares/anaconda3/envs/DataScience/lib/python3.8/site-packages/keras/engine/training.py\", line 1000, in run_step\n      outputs = model.train_step(data)\n    File \"/home/polivares/anaconda3/envs/DataScience/lib/python3.8/site-packages/keras/engine/training.py\", line 859, in train_step\n      y_pred = self(x, training=True)\n    File \"/home/polivares/anaconda3/envs/DataScience/lib/python3.8/site-packages/keras/utils/traceback_utils.py\", line 64, in error_handler\n      return fn(*args, **kwargs)\n    File \"/home/polivares/anaconda3/envs/DataScience/lib/python3.8/site-packages/keras/engine/base_layer.py\", line 1096, in __call__\n      outputs = call_fn(inputs, *args, **kwargs)\n    File \"/home/polivares/anaconda3/envs/DataScience/lib/python3.8/site-packages/keras/utils/traceback_utils.py\", line 92, in error_handler\n      return fn(*args, **kwargs)\n    File \"/home/polivares/anaconda3/envs/DataScience/lib/python3.8/site-packages/keras/engine/functional.py\", line 451, in call\n      return self._run_internal_graph(\n    File \"/home/polivares/anaconda3/envs/DataScience/lib/python3.8/site-packages/keras/engine/functional.py\", line 589, in _run_internal_graph\n      outputs = node.layer(*args, **kwargs)\n    File \"/home/polivares/anaconda3/envs/DataScience/lib/python3.8/site-packages/keras/utils/traceback_utils.py\", line 64, in error_handler\n      return fn(*args, **kwargs)\n    File \"/home/polivares/anaconda3/envs/DataScience/lib/python3.8/site-packages/keras/engine/base_layer.py\", line 1096, in __call__\n      outputs = call_fn(inputs, *args, **kwargs)\n    File \"/home/polivares/anaconda3/envs/DataScience/lib/python3.8/site-packages/keras/utils/traceback_utils.py\", line 92, in error_handler\n      return fn(*args, **kwargs)\n    File \"/home/polivares/anaconda3/envs/DataScience/lib/python3.8/site-packages/keras/layers/convolutional.py\", line 2255, in call\n      outputs = tf.compat.v1.nn.separable_conv2d(\nNode: 'model/block14_sepconv2/separable_conv2d'\nNo algorithm worked!  Error messages:\n  Profiling failure on CUDNN engine 1#TC: RESOURCE_EXHAUSTED: Out of memory while trying to allocate 51838992 bytes.\n  Profiling failure on CUDNN engine 1: RESOURCE_EXHAUSTED: Out of memory while trying to allocate 29368704 bytes.\n  Profiling failure on CUDNN engine 0#TC: RESOURCE_EXHAUSTED: Out of memory while trying to allocate 16777216 bytes.\n  Profiling failure on CUDNN engine 0: RESOURCE_EXHAUSTED: Out of memory while trying to allocate 16777216 bytes.\n  Profiling failure on CUDNN engine 2#TC: RESOURCE_EXHAUSTED: Out of memory while trying to allocate 26411008 bytes.\n  Profiling failure on CUDNN engine 2: RESOURCE_EXHAUSTED: Out of memory while trying to allocate 26411008 bytes.\n  Profiling failure on CUDNN engine 5#TC: RESOURCE_EXHAUSTED: Out of memory while trying to allocate 553779200 bytes.\n  Profiling failure on CUDNN engine 5: RESOURCE_EXHAUSTED: Out of memory while trying to allocate 553779200 bytes.\n\t [[{{node model/block14_sepconv2/separable_conv2d}}]] [Op:__inference_train_function_8560]"
     ]
    }
   ],
   "source": [
    "history = model.fit(train_set, epochs=10, validation_data=valid_set)"
   ]
  },
  {
   "cell_type": "code",
   "execution_count": null,
   "id": "6881fd5c",
   "metadata": {},
   "outputs": [],
   "source": [
    "model.predict(test_set)"
   ]
  },
  {
   "cell_type": "code",
   "execution_count": null,
   "id": "ec96019b",
   "metadata": {},
   "outputs": [],
   "source": [
    "for image, label in test_set:\n",
    "    print(\"Etiqueta real\",label)\n",
    "    print(\"Predicción\", model.predict(image))\n"
   ]
  }
 ],
 "metadata": {
  "kernelspec": {
   "display_name": "Python 3 (ipykernel)",
   "language": "python",
   "name": "python3"
  },
  "language_info": {
   "codemirror_mode": {
    "name": "ipython",
    "version": 3
   },
   "file_extension": ".py",
   "mimetype": "text/x-python",
   "name": "python",
   "nbconvert_exporter": "python",
   "pygments_lexer": "ipython3",
   "version": "3.10.0"
  }
 },
 "nbformat": 4,
 "nbformat_minor": 5
}
